Workbook

Sheet Bid Breakout
A1: DISASSEMBLE DYNAMICS, INC. - DEMOLITION BID BREAKOUT
A2: Orange County Corrections - FDC Isolation Cell Renovations in Units F & G (Solicitation Y25-790-RC) | 3503 Vision Blvd, Orlando FL | 10/27/2026
A3: Quantities scaled from 100% CDs (05/22/2024) & RFI log thru Add. #32 - verify in field. Blue = input; black = formula.
A5: # | B5: Description | C5: Ref (sheet / keynote) | D5: Qty | E5: Unit | F5: MH / Unit | G5: Base MH | H5: Adj MH (w/ security) | I5: Labor $ | J5: Equip / Rental $ | K5: Disposal $ | L5: Material / Other $ | M5: Direct Cost $
A6: BASE BID - SELECTIVE DEMOLITION (ARCHITECTURAL, MECHANICAL, PLUMBING, FIRE PROTECTION, ELECTRICAL, FIRE ALARM)
A7: B1 | B7: Remove detention plumbing fixtures & all accessories (WC, lav, combo fixture) | C7: AD201F/G D07; PD111F/G KN1 | D7: 34 | E7: EA | F7: 2.5 | G7: =D7*F7 -> 85 | H7: =G7*(1+Inputs!$B$8) -> 106.25 | I7: =H7*Inputs!$B$5 -> 2656.25 | J7: 0 | K7: 0 | L7: 0 | M7: =SUM(I7:L7) -> 2656.25
A8: B2 | B8: Remove restroom / shower partitions & shower drains | C8: AD201F/G D04; PD111F/G KN3 | D8: 2 | E8: LS | F8: 16 | G8: =D8*F8 -> 32 | H8: =G8*(1+Inputs!$B$8) -> 40 | I8: =H8*Inputs!$B$5 -> 1000 | J8: 0 | K8: 0 | L8: 0 | M8: =SUM(I8:L8) -> 1000
A9: B3 | B9: Remove existing plaster ceiling (incl. security mesh where present) | C9: AD201F/G legend; RFI #29 | D9: 1065 | E9: SF | F9: 0.04 | G9: =D9*F9 -> 42.6 | H9: =G9*(1+Inputs!$B$8) -> 53.25 | I9: =H9*Inputs!$B$5 -> 1331.25 | J9: 0 | K9: 0 | L9: 0 | M9: =SUM(I9:L9) -> 1331.25
A10: B4 | B10: Remove door, frame & all accessories | C10: AD201F D09 | D10: 1 | E10: EA | F10: 4 | G10: =D10*F10 -> 4 | H10: =G10*(1+Inputs!$B$8) -> 5 | I10: =H10*Inputs!$B$5 -> 125 | J10: 0 | K10: 0 | L10: 0 | M10: =SUM(I10:L10) -> 125
A11: B5 | B11: Remove above-slab sanitary/vent piping incl. 4" line to VTR & VTR | C11: PD111F/G KN1, KN5 | D11: 450 | E11: LF | F11: 0.12 | G11: =D11*F11 -> 54 | H11: =G11*(1+Inputs!$B$8) -> 67.5 | I11: =H11*Inputs!$B$5 -> 1687.5 | J11: 0 | K11: 0 | L11: 0 | M11: =SUM(I11:L11) -> 1687.5
A12: B6 | B12: Remove domestic piping, valves & controls in chases / walls | C12: PD112F/G KN2 | D12: 500 | E12: LF | F12: 0.12 | G12: =D12*F12 -> 60 | H12: =G12*(1+Inputs!$B$8) -> 75 | I12: =H12*Inputs!$B$5 -> 1875 | J12: 0 | K12: 0 | L12: 0 | M12: =SUM(I12:L12) -> 1875
A13: B7 | B13: Remove surface-mounted SS pipe enclosures (entire) & valve control cabinet | C13: PD112F/G KN1, KN3 | D13: 3 | E13: EA | F13: 8 | G13: =D13*F13 -> 24 | H13: =G13*(1+Inputs!$B$8) -> 30 | I13: =H13*Inputs!$B$5 -> 750 | J13: 0 | K13: 0 | L13: 0 | M13: =SUM(I13:L13) -> 750
A14: B8 | B14: Remove AHU + supply & OA ductwork as req'd for new AHU | C14: MD111F/G KN2; ED111G KN2 | D14: 2 | E14: EA | F14: 16 | G14: =D14*F14 -> 32 | H14: =G14*(1+Inputs!$B$8) -> 40 | I14: =H14*Inputs!$B$5 -> 1000 | J14: 0 | K14: 0 | L14: 0 | M14: =SUM(I14:L14) -> 1000
A15: B9 | B15: Remove RTU + return duct transition (piping disconnected by mech) | C15: MD112F/G KN2 | D15: 2 | E15: EA | F15: 20 | G15: =D15*F15 -> 40 | H15: =G15*(1+Inputs!$B$8) -> 50 | I15: =H15*Inputs!$B$5 -> 1250 | J15: 0 | K15: 0 | L15: 0 | M15: =SUM(I15:L15) -> 1250
A16: B10 | B16: Remove roof exhaust / supply fans (curbs & security bars remain) | C16: MD113F/G KN1-3 | D16: 4 | E16: EA | F16: 5 | G16: =D16*F16 -> 20 | H16: =G16*(1+Inputs!$B$8) -> 25 | I16: =H16*Inputs!$B$5 -> 625 | J16: 0 | K16: 0 | L16: 0 | M16: =SUM(I16:L16) -> 625
A17: B11 | B17: Remove ductwork, 12x12 exhaust duct, supply & return grilles, hangers | C17: MD111F/G, MD112F/G | D17: 300 | E17: LF | F17: 0.15 | G17: =D17*F17 -> 45 | H17: =G17*(1+Inputs!$B$8) -> 56.25 | I17: =H17*Inputs!$B$5 -> 1406.25 | J17: 0 | K17: 0 | L17: 0 | M17: =SUM(I17:L17) -> 1406.25
A18: B12 | B18: Remove 2" CHWS&R piping back to 3" reducer (supports remain) | C18: MD111G KN3 | D18: 40 | E18: LF | F18: 0.15 | G18: =D18*F18 -> 6 | H18: =G18*(1+Inputs!$B$8) -> 7.5 | I18: =H18*Inputs!$B$5 -> 187.5 | J18: 0 | K18: 0 | L18: 0 | M18: =SUM(I18:L18) -> 187.5
... A24: B18 | B24: Dust & noise control: tacky mats, poly at openings, HEPA vacs, broom clean nightly | C24: 02 4113 1.4.G; AD201 Gen. Note W | D24: 1 | E24: LS | F24: 40 | G24: =D24*F24 -> 40 | H24: =G24*(1+Inputs!$B$8) -> 50 | I24: =H24*Inputs!$B$5 -> 1250 | J24: 400 | K24: 0 | L24: 1200 | M24: =SUM(I24:L24) -> 2850
A25: B19 | B25: Security onboarding: FDLE Level 1 checks & badging / orientation | C25: 01 1100 1.9 | D25: 1 | E25: LS | F25: 24 | G25: =D25*F25 -> 24 | H25: =G25*(1+Inputs!$B$8) -> 30 | I25: =H25*Inputs!$B$5 -> 750 | J25: 0 | K25: 0 | L25: =Inputs!$B$6*Inputs!$B$16 -> 450 | M25: =SUM(I25:L25) -> 1200
A26: B20 | B26: C&D debris disposal - 30 yd dumpsters | C26: 02 4113 3.5 | D26: 4 | E26: PULL | F26: 0 | G26: =D26*F26 -> 0 | H26: =G26*(1+Inputs!$B$8) -> 0 | I26: =H26*Inputs!$B$5 -> 0 | J26: 0 | K26: =D26*Inputs!$B$11 -> 1400 | L26: 0 | M26: =SUM(I26:L26) -> 1400
B27: BASE BID - adjusted man-hours | H27: =SUM(H7:H26) -> 870.75
B28: BASE BID - crew-days (MH / crew / shift) | H28: =ROUNDUP(H27/(Inputs!$B$6*Inputs!$B$7),0) -> 19
B29: Direct cost (labor + equip + disposal + material) | M29: =SUM(M7:M26) -> 25518.75
B30: Lodging & per diem | M30: =Inputs!$B$15*H28*(Inputs!$B$13+Inputs!$B$6*Inputs!$B$14) -> 9595
B31: Contingency | M31: =M29*Inputs!$B$10 -> 1275.9375
B32: Profit ($/crew-day x crew-days) | M32: =Inputs!$B$9*H28 -> 19000
B33: BASE BID TOTAL | M33: =SUM(M29:M32) -> 55389.688
A35: ALTERNATE #1 - CMU WALL REMOVAL (8" SOLID GROUTED)
A36: A1.1 | B36: Remove 8" solid grouted CMU chase walls - Level 1 (+/-166 LF x 10'-8") | C36: SD111F/G Note 4; AD201F/G D01 | D36: 1770 | E36: SF | F36: 0.2 | G36: =D36*F36 -> 354 | H36: =G36*(1+Inputs!$B$8) -> 442.5 | I36: =H36*Inputs!$B$5 -> 11062.5 | J36: 0 | K36: 0 | L36: 0 | M36: =SUM(I36:L36) -> 11062.5
A37: A1.2 | B37: Remove 8" solid grouted CMU walls - Level 2 (+/-62 LF x 9') | C37: SD112F/G Note 4; AD202F/G D02 | D37: 560 | E37: SF | F37: 0.28 | G37: =D37*F37 -> 156.8 | H37: =G37*(1+Inputs!$B$8) -> 196 | I37: =H37*Inputs!$B$5 -> 4900 | J37: 0 | K37: 0 | L37: 0 | M37: =SUM(I37:L37) -> 4900
A38: A1.3 | B38: Cut dowels flush at walls where slab remains | C38: SD111F/G Note 4; SD501 A1 | D38: 60 | E38: LF | F38: 0.15 | G38: =D38*F38 -> 9 | H38: =G38*(1+Inputs!$B$8) -> 11.25 | I38: =H38*Inputs!$B$5 -> 281.25 | J38: 0 | K38: 0 | L38: 0 | M38: =SUM(I38:L38) -> 281.25
A39: A1.4 | B39: Concrete chainsaw / wall saw rental + blades/chains | C39: - | D39: 12 | E39: DAY | F39: 0 | G39: =D39*F39 -> 0 | H39: =G39*(1+Inputs!$B$8) -> 0 | I39: =H39*Inputs!$B$5 -> 0 | J39: =D39*450 -> 5400 | K39: 0 | L39: 0 | M39: =SUM(I39:L39) -> 5400
A40: A1.5 | B40: CMU disposal - 20 yd concrete dumpsters (+/-93 tons) | C40: - | D40: 4 | E40: PULL | F40: 0 | G40: =D40*F40 -> 0 | H40: =G40*(1+Inputs!$B$8) -> 0 | I40: =H40*Inputs!$B$5 -> 0 | J40: 0 | K40: =D40*Inputs!$B$12 -> 1400 | L40: 0 | M40: =SUM(I40:L40) -> 1400
B41: ALTERNATE #1 - adjusted man-hours | H41: =SUM(H36:H40) -> 649.75
B42: ALTERNATE #1 - crew-days (MH / crew / shift) | H42: =ROUNDUP(H41/(Inputs!$B$6*Inputs!$B$7),0) -> 14
B43: Direct cost (labor + equip + disposal + material) | M43: =SUM(M36:M40) -> 23043.75
B44: Lodging & per diem | M44: =Inputs!$B$15*H42*(Inputs!$B$13+Inputs!$B$6*Inputs!$B$14) -> 7070
B45: Contingency | M45: =M43*Inputs!$B$10 -> 1152.1875
B46: Profit ($/crew-day x crew-days) | M46: =Inputs!$B$9*H42 -> 14000
B47: ALTERNATE #1 TOTAL | M47: =SUM(M43:M46) -> 45265.938
...

Sheet Inputs
A1: FDC Isolation Cell Renovations - Units F & G | Demolition Bid Inputs
A2: Blue = editable input. Yellow = key assumption to confirm. All costs flow to 'Bid Breakout'.
A4: Input | B4: Value | C4: Source / note
A5: Labor rate ($/MH, flat - no night uptick) | B5: 25 | C5: Shawn standing input: $25/hr flat
A6: Crew size (men) | B6: 6 | C6: Night crew
A7: Shift length (hrs) | B7: 8 | C7: Base bid = night work Mon-Fri (01 2300); 01 1100 1.7.A daytime hrs = Alt No. 1
A8: Security / productivity factor on labor | B8: 0.25 | C8: Escorts, vestibules, tool & debris accounting, no storage after hours (01 1100 1.9, RFI #43)
A9: Profit ($ per crew-day) | B9: 1000 | C9: Shawn standing input: $1,000/day
A10: Contingency (% of direct cost) | B10: 0.05 | C10: Shawn standing input: 5%
A11: C&D dumpster ($/pull) | B11: 350 | C11: Orlando independent bldg rule $350/pull - confirm hauler can service FDC secure lot
A12: Concrete/CMU dumpster ($/pull, 20 yd) | B12: 350 | C12: Orlando rate assumed = C&D; ~24 tons per full load
A13: Lodging ($/night, crew house) | B13: 265 | C13: Lake City to Orlando ~2.5 hrs each way; night shifts
A14: Per diem ($/man/day) | B14: 40 | C14: Shawn standing input
A15: Include lodging & per diem? (1 = yes, 0 = no) | B15: 1 | C15: Set to 0 if crew commutes
A16: FDLE Level 1 background check ($/man) | B16: 75 | C16: 01 1100 1.9 - contractor pays; ~2 wk turnaround (RFI #64)

Sheet Scope of Work
B1: DEMOLITION SCOPE OF WORK - FDC Isolation Cell Renovations in Units F & G
B3: DEMOLITION SCOPE OF WORK
A4: 1 | B4: Remove existing detention plumbing fixtures and all accessories - 16 WC, 16 lavatories, 2 combination fixtures (Plan Note D07, Plumbing Note 1)
A5: 2 | B5: Remove existing restroom / shower partitions and shower drains, Units F & G (Plan Note D04, Plumbing Note 3)
A6: 3 | B6: Remove existing plaster ceilings in hatched areas incl. security mesh where present, +/-1,065 SF (Plan Legend, RFI #29)
A7: 4 | B7: Remove existing door, frame and all accessories, Unit F, 1 EA (Plan Note D09)
A8: 5 | B8: Remove all above-slab sanitary and vent piping in hatched areas incl. 4" sanitary line up to and including the 4" VTR, Units F & G (Plumbing Notes 1, 5)
A9: 6 | B9: Remove all domestic plumbing in chases and walls incl. valves, fixtures and associated controls, surface-mounted stainless steel pipe enclosures in their entirety, and the existing valve control cabinet (Plumbing Notes 1, 2, 3)
A10: 7 | B10: Remove existing AHUs and portions of supply and outdoor air ductwork as required for new AHUs, 2 EA (Mech Note 2, Elec Note 2)
A11: 8 | B11: Remove existing RTUs and return duct transitions after chilled water and condensate piping are disconnected by mechanical, 2 EA (Mech Note 2)
A12: 9 | B12: Remove existing roof exhaust and supply fans, curbs and security bars to remain, 4 EA (Mech Notes 1, 2, 3)
A13: 10 | B13: Remove existing supply / return grilles and associated ductwork, hangers, straps and supports, incl. 12x12 exhaust duct to 2nd floor (Mech Notes 1, 7, 9)
A14: 11 | B14: Remove 2" CHWS&R piping back to 3" reducer, supports to remain, Unit G (Mech Note 3)
A15: 12 | B15: Remove sprinkler branch piping and heads shown for demolition, +/-360 LF, after drain-down by the fire protection contractor (FPD111, FPD112)
... A21: 18 | B21: Legally dispose of all demolition debris off-site; owner retains first right of refusal on salvage per joint damage survey (Gen. Notes D, L; Spec 02 4113 3.5)
B23: ALTERNATES
A24: 1 | B24: ALTERNATE #1: Remove 8" solid grouted CMU chase walls - Level 1 +/-166 LF (+/-1,770 SF) and Level 2 +/-62 LF (+/-560 SF); cut dowels flush where slab remains, following EOR field review (Struct Notes 1, 4; Plan Notes D01, D02)
A25: 2 | B25: ALTERNATE #2: Sawcut and remove 4" slab-on-grade, thickened slab, footings and continuous bars, Unit F +/-555 SF / Unit G +/-569 SF (Struct Note 3; Plan Notes D11, D13; SD501 A4, A6)
A26: 3 | B26: ALTERNATE #3: Wall / slab cuts for new plumbing 9 EA, partial wall demo for new door 1 EA, 12" openings in precast wall panels 4 EA, precast mezzanine slab openings 2 EA, roof panel / metal deck openings 3 EA, incl. GPR / X-ray scanning allowance (Plan Notes D03, D10; SD112F/G, SD121, SD501; RFI #32)
A27: 4 | B27: ALTERNATE #4: Grind dowels / wall base down 1/2" minimum below top of slab where slab remains (Struct Note 4)
A28: 5 | B28: ALTERNATE #5: Negative air machines and full-height poly dust containment, Units F & G
A29: 6 | B29: ALTERNATE #6: Daytime work (Spec 01 2300 Alternate No. 1) - DDD price unchanged (flat labor rate)
B31: EXCLUSIONS
B32: - All patching, repair, slab repair per specs, roof patching, curbs and caps, fireproofing repair, and prep for new finishes (Spec 01 7329; Mech Note 2; RFI #21)
B33: - Excavation, trenching and backfill below slab; disconnecting / capping / grout-abandoning underslab and below-grade piping (Plumbing Notes 2, 4, 5)
B34: - Disconnect, cap and make-safe of all utilities - electrical, plumbing, chilled water, sprinkler drain-down and impairment, and fire alarm system programming / bypass by the respective trades
B35: - Removal of conduit and wiring beyond the nearest junction box or back to the panel / source (Elec Gen. Note 4)
B36: - Shoring: included is limited to non-load-bearing masonry; load-bearing wall shoring, shoring design, structural engineering, PE survey and stamped drawings excluded (RFI #46; Spec 02 4113 3.1.C; S001)
B37: - Furnishing / installing lintels, bearing plates, jamb reinforcement, security bars at penetrations, and grouting (RFI #76)
B38: - Plywood / steel security covers at openings left overnight, temporary partitions and guardrails by GC (01 1100 1.9)
B39: - Hazardous materials (asbestos, lead, PCB ballasts) identification, abatement or disposal - no survey provided
B40: - Crane or rooftop rigging for RTUs / fans; detention equipment and security systems (RFI #79, #82)
B41: - Domestic Water Piping Replacement project (FDC_DW drawings) and ACT grid / tile removal and replacement
B42: - Items to remain: existing fixtures to remain (Plumbing Note 6), existing lights in dayroom, equipment within NIC rooms, roof curbs and security bars
... B49: - Security time, escorts and FDLE background checks for DDD crew included as listed; delays from inmate movement, lockdowns or denied access are by change order.
