Workbook

Sheet Summary & Scope
B1: FINE WINE & GOOD SPIRITS - WHITE OAK PA | DEMOLITION BID (DISASSEMBLE DYNAMICS, INC.)
B2: Fine Wine & Good Spirits (PLCB Store #0282) - Oak Park Mall, 2001 Lincoln Way Suite 250, White Oak PA 15131 | GC: Marco Contractors (Calle Barrett, job fw8840) | Axis Architecture D100 (Addendum 1 10/26/26) | PA PREVAILING WAGE (L&I Serial 26-09265) | Proposal DDD-2026/1028R1
B4: PRICE SUMMARY
B5: BASE BID | C5: ='Demo Bid - DDD'!L28 -> 25910
B6: Alternate No. 1 - strip paint / remove mastic / grind concrete floor (approx. 4,597 SF) | C6: ='Demo Bid - DDD'!L38 -> 9330
B7: Alternate No. 2 - sanitary trench sawcut & slab removal (85 LF) | C7: ='Demo Bid - DDD'!L49 -> 3630
B9: SCOPE OF WORK (as written in the proposal)
B10: OUR SCOPE OF WORK (INCLUSIONS)
B11: Remove existing ceiling grid and tile throughout the suite, approx. 4,597 SF (D100 Note 2)
B12: Remove existing light fixtures throughout, approx. 58 EA (D100 Note 2)
B13: Remove existing flooring throughout, approx. 4,597 SF (D100 Note 2)
B14: Remove existing gypsum wallboard at the demising walls, metal studs to remain, approx. 221 LF (Addendum 1, D100 Note 6)
B15: Remove existing interior walls and closet partitions, approx. 30 LF (D100 Note 1)
B16: Remove existing doors, frames and hardware, 2 locations (D100 Note 4)
B17: Remove portion of existing storefront, approx. 14 LF (D100 Note 5)
B18: Remove existing water filtering equipment and associated piping and conduit after disconnect by others (Addendum 1, D100 Note 7)
B19: Remove existing mop sink / plumbing fixture after capping below slab by plumber (D100 Note 3)
B20: Remove abandoned electrical devices, boxes, plates and wiring back to the nearest junction box
... B34: Removal of metal studs at demising walls (to remain per Addendum 1).

Sheet Inputs
A1: Fine Wine & Good Spirits - White Oak PA | Demolition Estimate Inputs
A2: Blue = editable input. Yellow = assumption to confirm. All costs flow to the Demo Bid tab.
A4: Input | B4: Value | C4: Note
A5: PW Laborer Class 02 base wage ($/hr) | B5: 27.97 | C5: PA L&I Serial 26-09265, Building, eff. 1/1/2026 (Addendum 1 Att. 1) - confirm demo classification
A6: PW Laborer fringe ($/hr) | B6: 20.46 | C6: Same determination - pay as cash or bona fide benefits
A7: Payroll burden on base wage (%) | B7: 0.22 | C7: FICA 7.65% + FUTA/SUTA + demo work comp - confirm with payroll
A8: Labor rate ($/MH, loaded prevailing wage) | B8: =B5+B6+B5*B7 -> 54.5834 | C8: Replaces the standing $25/MH flat rate on this prevailing wage job
A9: Crew size (men) | B9: 6 | C9: Standing input
A10: Shift length (hrs) | B10: 8 | C10: Day work in mall - after-hours not included
A11: Profit ($ per crew-day) | B11: 1000 | C11: Standing input
A12: Contingency (% of direct) | B12: 0.05 | C12: Standing input
A13: C&D dumpster 30 yd ($/pull) | B13: 650 | C13: Pittsburgh-area rate not on file - confirm with mall / local hauler
A14: Concrete dumpster 20 yd ($/pull) | B14: 550 | C14: PA rate not on file - confirm
A15: Lodging ($/night, crew house) | B15: 265 | C15: Standing rate; travel job ~950 mi from Lake City
A16: Per diem ($/man/day) | B16: 40 | C16: Standing input
A17: Include lodging & per diem? (1 = yes, 0 = no) | B17: 1 | C17: Set to 0 if a local crew is used
A18: Lodging nights per crew-day | B18: 1.4 | C18: 7 nights per 5 work days
A19: Certified payroll / PW compliance admin ($ LS) | B19: 450 | C19: Weekly certified payrolls, L&I postings

Sheet Demo Bid - DDD
A1: DISASSEMBLE DYNAMICS, INC. - DEMOLITION BID BREAKOUT
A2: Fine Wine & Good Spirits (PLCB Store #0282) - Oak Park Mall, 2001 Lincoln Way Suite 250, White Oak PA 15131 | GC: Marco Contractors (Calle Barrett, job fw8840) | Axis Architecture D100 (Addendum 1 10/26/26) | PA PREVAILING WAGE (L&I Serial 26-09265)
A3: Quantities scaled from Addendum 1 D100 at 1/8" = 1'-0" and A100 area split (4,597 SF) - see markup tabs. Existing ceiling, flooring and lighting types not shown - verify at walk. | N3: DEMOLITION MARKUP - D100 (ADDENDUM 1)
A5: # | B5: Description | C5: Ref | D5: Qty | E5: Unit | F5: MH / Unit | G5: MH | H5: Labor $ | I5: Equip / Rental $ | J5: Disposal $ | K5: Other $ | L5: Direct $
A6: BASE BID - INTERIOR DEMOLITION (D100 ADDENDUM 1)
A7: D1 | B7: Remove ceiling grid & tile throughout (Note 2) | C7: D100 Note 2; Gen. Notes | D7: 4597 | E7: SF | F7: 0.012 | G7: =D7*F7 -> 55.164 | H7: =G7*Inputs!$B$8 -> 3011.0387 | I7: 0 | J7: 0 | K7: 0 | L7: =SUM(H7:K7) -> 3011.0387
A8: D2 | B8: Remove light fixtures throughout (approx. 1 per 80 SF) | C8: D100 Note 2 | D8: 58 | E8: EA | F8: 0.5 | G8: =D8*F8 -> 29 | H8: =G8*Inputs!$B$8 -> 1582.9186 | I8: 0 | J8: 0 | K8: 0 | L8: =SUM(H8:K8) -> 1582.9186
A9: D3 | B9: Remove flooring throughout (assumed carpet / VCT / resilient on slab) | C9: D100 Note 2; A103 | D9: 4597 | E9: SF | F9: 0.01 | G9: =D9*F9 -> 45.97 | H9: =G9*Inputs!$B$8 -> 2509.1989 | I9: 0 | J9: 0 | K9: 0 | L9: =SUM(H9:K9) -> 2509.1989
A10: D4 | B10: Remove existing gypsum wallboard at demising walls - metal studs to remain (+/-221 LF x ~12') | C10: Add. 1 Note 6 | D10: 2654 | E10: SF | F10: 0.014 | G10: =D10*F10 -> 37.156 | H10: =G10*Inputs!$B$8 -> 2028.1008 | I10: 0 | J10: 0 | K10: 0 | L10: =SUM(H10:K10) -> 2028.1008
A11: D5 | B11: Remove interior walls / closet partitions (+/-30 LF) | C11: D100 Note 1 | D11: 30 | E11: LF | F11: 0.3 | G11: =D11*F11 -> 9 | H11: =G11*Inputs!$B$8 -> 491.2506 | I11: 0 | J11: 0 | K11: 0 | L11: =SUM(H11:K11) -> 491.2506
A12: D6 | B12: Remove doors, frames & hardware (2 locations incl. rear pair) | C12: D100 Note 4; A100 door 9 | D12: 2 | E12: EA | F12: 3 | G12: =D12*F12 -> 6 | H12: =G12*Inputs!$B$8 -> 327.5004 | I12: 0 | J12: 0 | K12: 0 | L12: =SUM(H12:K12) -> 327.5004
A13: D7 | B13: Remove portion of storefront (+/-14 LF) | C13: D100 Note 5 | D13: 14 | E13: LF | F13: 1 | G13: =D13*F13 -> 14 | H13: =G13*Inputs!$B$8 -> 764.1676 | I13: 0 | J13: 0 | K13: 0 | L13: =SUM(H13:K13) -> 764.1676
A14: D8 | B14: Remove water filtering equipment & associated piping/conduit after disconnect by plumber/electrician | C14: Add. 1 Note 7 | D14: 1 | E14: LS | F14: 6 | G14: =D14*F14 -> 6 | H14: =G14*Inputs!$B$8 -> 327.5004 | I14: 0 | J14: 0 | K14: 0 | L14: =SUM(H14:K14) -> 327.5004
A15: D9 | B15: Remove mop sink / plumbing fixture after cap below slab by plumber | C15: D100 Note 3 | D15: 1 | E15: EA | F15: 2 | G15: =D15*F15 -> 2 | H15: =G15*Inputs!$B$8 -> 109.1668 | I15: 0 | J15: 0 | K15: 0 | L15: =SUM(H15:K15) -> 109.1668
A16: D10 | B16: Remove abandoned electrical devices, boxes & wiring back to nearest J-box | C16: Gen. Demo Notes | D16: 4597 | E16: SF | F16: 0.003 | G16: =D16*F16 -> 13.791 | H16: =G16*Inputs!$B$8 -> 752.75967 | I16: 0 | J16: 0 | K16: 0 | L16: =SUM(H16:K16) -> 752.75967
A17: D11 | B17: Remove misc. equipment - TV brackets, fire extinguisher cabinets, owner items per direction | C17: Gen. Demo Notes | D17: 1 | E17: LS | F17: 6 | G17: =D17*F17 -> 6 | H17: =G17*Inputs!$B$8 -> 327.5004 | I17: 0 | J17: 0 | K17: 0 | L17: =SUM(H17:K17) -> 327.5004
A18: D12 | B18: Mall load-out via service corridor, protection of items to remain, daily clean & broom clean | C18: Gen. Demo Notes | D18: 1 | E18: LS | F18: 15 | G18: =D18*F18 -> 15 | H18: =G18*Inputs!$B$8 -> 818.751 | I18: 0 | J18: 0 | K18: 0 | L18: =SUM(H18:K18) -> 818.751
... A20: D14 | B20: Consumables - blades, bags, poly, PPE | C20: - | D20: 1 | E20: LS | F20: 0 | G20: =D20*F20 -> 0 | H20: =G20*Inputs!$B$8 -> 0 | I20: 0 | J20: 0 | K20: 500 | L20: =SUM(H20:K20) -> 500
A21: D15 | B21: Certified payroll / prevailing wage compliance | C21: Addendum 1 | D21: 1 | E21: LS | F21: 0 | G21: =D21*F21 -> 0 | H21: =G21*Inputs!$B$8 -> 0 | I21: 0 | J21: 0 | K21: =Inputs!$B$19 -> 450 | L21: =SUM(H21:K21) -> 450
A22: D16 | B22: C&D disposal - 30 yd dumpsters | C22: Gen. Demo Notes | D22: 4 | E22: PULL | F22: 0 | G22: =D22*F22 -> 0 | H22: =G22*Inputs!$B$8 -> 0 | I22: 0 | J22: =D22*Inputs!$B$13 -> 2600 | K22: 0 | L22: =SUM(H22:K22) -> 2600
B23: BASE BID - man-hours / crew-days | G23: =SUM(G7:G22) -> 239.081 | H23: =MAX(1,ROUNDUP(G23/(Inputs!$B$9*Inputs!$B$10),0)) -> 5
B24: Direct cost | L24: =SUM(L7:L22) -> 16999.854
B25: Lodging & per diem | L25: =Inputs!$B$17*H23*(Inputs!$B$18*Inputs!$B$15+Inputs!$B$9*Inputs!$B$16) -> 3055
B26: Contingency | L26: =L24*Inputs!$B$12 -> 849.99269
B27: Profit ($/crew-day x crew-days) | L27: =Inputs!$B$11*H23 -> 5000
B28: BASE BID TOTAL | L28: =ROUNDUP(SUM(L24:L27),-1) -> 25910
A30: ALTERNATE #1 - STRIP PAINT / REMOVE MASTIC / GRIND CONCRETE FLOOR
A31: A1.1 | B31: Strip paint & remove mastic from existing concrete floor to receive new finish (sealer by others) | C31: Gen. Demo Notes; A103 | D31: 4597 | E31: SF | F31: 0.015 | G31: =D31*F31 -> 68.955 | H31: =G31*Inputs!$B$8 -> 3763.7983 | I31: 1400 | J31: 0 | K31: 0 | L31: =SUM(H31:K31) -> 5163.7983
A32: A1.2 | B32: C&D disposal | C32: - | D32: 1 | E32: PULL | F32: 0 | G32: =D32*F32 -> 0 | H32: =G32*Inputs!$B$8 -> 0 | I32: 0 | J32: =D32*Inputs!$B$13 -> 650 | K32: 0 | L32: =SUM(H32:K32) -> 650
B33: ALT #1 - man-hours / crew-days | G33: =SUM(G31:G32) -> 68.955 | H33: =MAX(1,ROUNDUP(G33/(Inputs!$B$9*Inputs!$B$10),0)) -> 2
B34: Direct cost | L34: =SUM(L31:L32) -> 5813.7983
B35: Lodging & per diem | L35: =Inputs!$B$17*H33*(Inputs!$B$18*Inputs!$B$15+Inputs!$B$9*Inputs!$B$16) -> 1222
B36: Contingency | L36: =L34*Inputs!$B$12 -> 290.68992
B37: Profit ($/crew-day x crew-days) | L37: =Inputs!$B$11*H33 -> 2000
B38: ALT #1 TOTAL | L38: =ROUNDUP(SUM(L34:L37),-1) -> 9330
A40: ALTERNATE #2 - SANITARY TRENCH SAWCUT & SLAB REMOVAL (85 LF PER ITB)
A41: A2.1 | B41: Sawcut slab both sides of trench (85 LF x 2 sides) | C41: ITB - concrete trench 85 LF | D41: 170 | E41: LF | F41: 0.06 | G41: =D41*F41 -> 10.2 | H41: =G41*Inputs!$B$8 -> 556.75068 | I41: 350 | J41: 0 | K41: 0 | L41: =SUM(H41:K41) -> 906.75068
A42: A2.2 | B42: Break & remove trench slab (approx. 2' wide) - excavation & pour-back by others | C42: ITB | D42: 170 | E42: SF | F42: 0.05 | G42: =D42*F42 -> 8.5 | H42: =G42*Inputs!$B$8 -> 463.9589 | I42: 0 | J42: 0 | K42: 0 | L42: =SUM(H42:K42) -> 463.9589
A43: A2.3 | B43: Concrete disposal - 20 yd dumpster | C43: - | D43: 1 | E43: PULL | F43: 0 | G43: =D43*F43 -> 0 | H43: =G43*Inputs!$B$8 -> 0 | I43: 0 | J43: =D43*Inputs!$B$14 -> 550 | K43: 0 | L43: =SUM(H43:K43) -> 550
B44: ALT #2 - man-hours / crew-days | G44: =SUM(G41:G43) -> 18.7 | H44: =MAX(1,ROUNDUP(G44/(Inputs!$B$9*Inputs!$B$10),0)) -> 1
...

Sheet Markup - D100 Demo Plan
A1: MARKUP: D100 Demo Plan (full-size PDF: FWGS_White_Oak_Demo_Markup.pdf)

Sheet Markup - D100 Enlarged
A1: MARKUP: D100 Enlarged (full-size PDF: FWGS_White_Oak_Demo_Markup.pdf)
