Workbook

Sheet Summary & Scope
B1: PALMS MEDICAL GROUP - LAKE SHORE REMODEL | DEMOLITION + FLOORING
B2: 351 NE Franklin St, Lake City FL 32055 | Owner: Lake Shore Hospital Authority | 8,616 GSF outpatient clinic
B4: PRICE SUMMARY
B5: Demolition - Base bid (interior + site) - Disassemble Dynamics | C5: ='Demo Bid - DDD'!L74 -> 52140.887
B6: Demolition - Alt #1 exterior CMU walls | C6: ='Demo Bid - DDD'!L49 -> 8055.75
B7: Demolition - Alt #2 sawcutting at site demo limits | C7: ='Demo Bid - DDD'!L57 -> 1525
B8: Demolition - Alt #3 mastic removal / grinding | C8: ='Demo Bid - DDD'!L65 -> 9244.75
B9: Flooring - Wayne's Carpet Plus | C9: ='Flooring - Wayne''s'!K14 -> 57897.938
B10: Combined base (demo base + flooring) | C10: =C5+C9 -> 110038.82
B12: SCOPE OF WORK
B13: DEMOLITION SCOPE OF WORK (Disassemble Dynamics)
B14: 1. Complete interior demolition of all items in the building except roof drains above ceiling, main MDP and panels; remove interior partitions to deck, +/-850 LF (A1 Demo Note)
B15: 2. Remove drywall on exterior walls down to fur channel, +/-3,500 SF (A1 Demo Note)
B16: 3. Remove ceilings and grid throughout, incl. M100 data room ceiling only, +/-7,700 SF (A1, M100 Note)
B17: 4. Remove existing floor finishes throughout, +/-7,590 SF (A1 Demo Note)
B18: 5. Remove doors, frames and hardware, +/-40 EA; casework, countertops and reception desk, +/-100 LF (A1)
B19: 6. Remove plumbing fixtures, +/-30 EA, after capping by plumbing contractor (A1)
B20: 7. Remove light fixtures, devices, conduit and wire back to the nearest junction box; HVAC ductwork, diffusers, grilles and hangers (A1 Demo Note)
B21: 8. Remove existing storefront and glazing at new entrance and center section for new exterior door, +/-60 LF (A1, A1.1)
B22: 9. Remove existing curb and gutter 274 LF, asphalt pavement 1,574 SF, concrete 489 SF (Site Demo Notes 1, 2, 3)
B23: 10. Remove existing trees incl. stump grinding, 8 EA (Site Demo Note 4)
... B42: - Wood base WM618 / WM725, quarter round, chair rail and crown (trim carpentry); moisture mitigation beyond allowance; furniture moving

Sheet Inputs
A1: Palms Medical Group / Lake Shore Hospital Authority - 351 NE Franklin St, Lake City FL | Estimate Inputs
A2: Blue = editable input. Yellow = assumption to confirm. All costs flow to the estimate tabs.
A4: Input | B4: Value | C4: Note
A5: DEMOLITION (Disassemble Dynamics)
A6: Labor rate ($/MH, flat) | B6: 25 | C6: Standing input
A7: Crew size (men) | B7: 6 | C7: Local - Lake City, daytime
A8: Shift length (hrs) | B8: 8
A9: Profit ($ per crew-day) | B9: 1000 | C9: Standing input
A10: Contingency (% of direct) | B10: 0.05 | C10: Standing input
A11: C&D dumpster 30 yd ($/pull) | B11: 450 | C11: Lake City rate not on file - confirm with hauler
A12: Concrete/asphalt dumpster 20 yd ($/pull) | B12: 450 | C12: Lake City rate not on file - confirm
A13: FLOORING (Wayne's Carpet Plus)
A14: CT - Mohawk 559 Anodized Lapis material ($/SF) | B14: 3.25 | C14: Assumed carpet tile - get distributor quote
A15: CT adhesive / release ($/SF) | B15: 0.2
A16: CT install labor ($/SF) | B16: 0.85
A17: CT waste factor | B17: 0.07
A18: LVT - Flexco Natural Elements American Cherry 610 material ($/SF) | B18: 3.5 | C18: Get Flexco distributor quote
A19: LVT adhesive ($/SF) | B19: 0.25 | C19: Per Flexco recommended adhesive
A20: LVT install labor ($/SF) | B20: 1.4
A21: LVT waste factor | B21: 0.08
A22: Shower floor tile 2x2 sheet ceramic - material incl. setting & grout ($/SF) | B22: 14 | C22: Color w/ PMG
A23: Shower floor tile install ($/SF) | B23: 18 | C23: Small area - see minimum
A24: Shower tile minimum charge ($) | B24: 650
A25: Floor prep / patch & skim allowance ($/SF of floor) | B25: 0.45 | C25: Existing slab condition unknown until demo
A26: Transition strips ($/EA installed) | B26: 65 | C26: Gen. Note 2 & 3
A27: Freight / delivery ($) | B27: 450
A28: Overhead & profit markup (Wayne's) | B28: 0.25 | C28: Set Wayne's margin

Sheet Demo Bid - DDD
A1: DISASSEMBLE DYNAMICS, INC. - DEMOLITION BID BREAKOUT
A2: Remodel & Alterations - Lake Shore Hospital Authority / Palms Medical Group, 351 NE Franklin St, Lake City FL (TCCS plans 08/10/2026; site plan 02/02/2026)
A3: Quantities scaled from A1 / A1.1 / A5 and taken from civil Demolition Notes & Estimated Quantities - verify in field. | N3: DEMOLITION MARKUPS - A1 DEMO PLAN, A1.1 STOREFRONT, SITE DEMO, FLOOR REMOVAL, CEILING REMOVAL
A5: # | B5: Description | C5: Ref | D5: Qty | E5: Unit | F5: MH / Unit | G5: MH | H5: Labor $ | I5: Equip / Rental $ | J5: Disposal $ | K5: Other $ | L5: Direct $
A6: BASE BID - INTERIOR SELECTIVE DEMOLITION (COMPLETE GUT)
A7: D1 | B7: Remove interior partitions (stud & drywall) to deck, incl. framing | C7: A1 complete demo note | D7: 850 | E7: LF | F7: 0.25 | G7: =D7*F7 -> 212.5 | H7: =G7*Inputs!$B$6 -> 5312.5 | I7: 0 | J7: 0 | K7: 0 | L7: =SUM(H7:K7) -> 5312.5
A8: D2 | B8: Remove drywall on exterior walls down to fur channel | C8: A1 complete demo note | D8: 3500 | E8: SF | F8: 0.012 | G8: =D8*F8 -> 42 | H8: =G8*Inputs!$B$6 -> 1050 | I8: 0 | J8: 0 | K8: 0 | L8: =SUM(H8:K8) -> 1050
A9: D3 | B9: Remove ceilings & grid throughout (incl. M100 data room ceiling only) | C9: A1; M100 note; Ceiling Removal markup | D9: 7700 | E9: SF | F9: 0.012 | G9: =D9*F9 -> 92.4 | H9: =G9*Inputs!$B$6 -> 2310 | I9: 0 | J9: 0 | K9: 0 | L9: =SUM(H9:K9) -> 2310
A10: D4 | B10: Remove existing floor finishes (DDD-owned scraper) | C10: A1; Floor Removal markup | D10: 7590 | E10: SF | F10: 0.012 | G10: =D10*F10 -> 91.08 | H10: =G10*Inputs!$B$6 -> 2277 | I10: 0 | J10: 0 | K10: 0 | L10: =SUM(H10:K10) -> 2277
A11: D5 | B11: Remove doors, frames & hardware | C11: A1 | D11: 40 | E11: EA | F11: 1 | G11: =D11*F11 -> 40 | H11: =G11*Inputs!$B$6 -> 1000 | I11: 0 | J11: 0 | K11: 0 | L11: =SUM(H11:K11) -> 1000
A12: D6 | B12: Remove casework, countertops & reception desk | C12: A1 | D12: 100 | E12: LF | F12: 0.3 | G12: =D12*F12 -> 30 | H12: =G12*Inputs!$B$6 -> 750 | I12: 0 | J12: 0 | K12: 0 | L12: =SUM(H12:K12) -> 750
A13: D7 | B13: Remove plumbing fixtures (WC, lav/exam sinks, shower, mop sink) - after cap by plumber | C13: A1 | D13: 30 | E13: EA | F13: 1.5 | G13: =D13*F13 -> 45 | H13: =G13*Inputs!$B$6 -> 1125 | I13: 0 | J13: 0 | K13: 0 | L13: =SUM(H13:K13) -> 1125
A14: D8 | B14: Remove light fixtures, devices, conduit & wire back to nearest J-box (MDP & panels remain) | C14: A1 complete demo note | D14: 7700 | E14: SF | F14: 0.008 | G14: =D14*F14 -> 61.6 | H14: =G14*Inputs!$B$6 -> 1540 | I14: 0 | J14: 0 | K14: 0 | L14: =SUM(H14:K14) -> 1540
A15: D9 | B15: Remove HVAC ductwork, diffusers, grilles & hangers (roof drains remain) | C15: A1 complete demo note | D15: 7700 | E15: SF | F15: 0.008 | G15: =D15*F15 -> 61.6 | H15: =G15*Inputs!$B$6 -> 1540 | I15: 0 | J15: 0 | K15: 0 | L15: =SUM(H15:K15) -> 1540
A16: D10 | B16: Remove existing storefront & glazing (new entrance + center section) | C16: A1, A1.1 | D16: 60 | E16: LF | F16: 0.5 | G16: =D16*F16 -> 30 | H16: =G16*Inputs!$B$6 -> 750 | I16: 0 | J16: 0 | K16: 0 | L16: =SUM(H16:K16) -> 750
A17: D11 | B17: Load-out, protection of X-ray 120 & MDP, broom clean | C17: A1 | D17: 1 | E17: LS | F17: 40 | G17: =D17*F17 -> 40 | H17: =G17*Inputs!$B$6 -> 1000 | I17: 0 | J17: 0 | K17: 0 | L17: =SUM(H17:K17) -> 1000
A18: D12 | B18: Small equipment rental - debris carts & rolling scaffolds (2) for ceiling / high work | C18: - | D18: 16 | E18: DAY | F18: 0 | G18: =D18*F18 -> 0 | H18: =G18*Inputs!$B$6 -> 0 | I18: =D18*50 -> 800 | J18: 0 | K18: 0 | L18: =SUM(H18:K18) -> 800
A19: D13 | B19: Consumables - saw blades, debris bags, poly, floor protection, PPE | C19: - | D19: 1 | E19: LS | F19: 0 | G19: =D19*F19 -> 0 | H19: =G19*Inputs!$B$6 -> 0 | I19: 0 | J19: 0 | K19: 900 | L19: =SUM(H19:K19) -> 900
A20: D14 | B20: C&D disposal - 30 yd dumpsters | C20: - | D20: 8 | E20: PULL | F20: 0 | G20: =D20*F20 -> 0 | H20: =G20*Inputs!$B$6 -> 0 | I20: 0 | J20: =D20*Inputs!$B$11 -> 3600 | K20: 0 | L20: =SUM(H20:K20) -> 3600
B21: INTERIOR BASE BID - man-hours / crew-days | G21: =SUM(G7:G20) -> 746.18 | H21: =ROUNDUP(G21/(Inputs!$B$7*Inputs!$B$8),0) -> 16
B22: Direct cost | L22: =SUM(L7:L20) -> 23954.5
B23: Contingency | L23: =L22*Inputs!$B$10 -> 1197.725
B24: Profit ($/crew-day x crew-days) | L24: =Inputs!$B$9*H21 -> 16000
B25: INTERIOR BASE BID TOTAL | L25: =SUM(L22:L24) -> 41152.225
A27: BASE BID - SITE DEMOLITION
A28: S1 | B28: Remove existing asphalt pavement | C28: Site Demo Note 2 | D28: 1574 | E28: SF | F28: 0.01 | G28: =D28*F28 -> 15.74 | H28: =G28*Inputs!$B$6 -> 393.5 | I28: 0 | J28: 0 | K28: 0 | L28: =SUM(H28:K28) -> 393.5
A29: S2 | B29: Remove existing concrete | C29: Site Demo Note 3 | D29: 489 | E29: SF | F29: 0.03 | G29: =D29*F29 -> 14.67 | H29: =G29*Inputs!$B$6 -> 366.75 | I29: 0 | J29: 0 | K29: 0 | L29: =SUM(H29:K29) -> 366.75
A30: S3 | B30: Remove existing curb & gutter | C30: Site Demo Note 1 | D30: 274 | E30: LF | F30: 0.08 | G30: =D30*F30 -> 21.92 | H30: =G30*Inputs!$B$6 -> 548 | I30: 0 | J30: 0 | K30: 0 | L30: =SUM(H30:K30) -> 548
A31: S4 | B31: Remove existing trees incl. stump grinding & haul-off | C31: Site Demo Note 4 | D31: 8 | E31: EA | F31: 6 | G31: =D31*F31 -> 48 | H31: =G31*Inputs!$B$6 -> 1200 | I31: 0 | J31: 0 | K31: 0 | L31: =SUM(H31:K31) -> 1200
A32: S5 | B32: Skid steer w/ breaker (3 days) + mini-ex (2 days) + stump grinder (2 days) | C32: - | D32: 1 | E32: LS | F32: 0 | G32: =D32*F32 -> 0 | H32: =G32*Inputs!$B$6 -> 0 | I32: 2850 | J32: 0 | K32: 0 | L32: =SUM(H32:K32) -> 2850
A33: S6 | B33: Concrete / asphalt disposal - 20 yd dumpsters (+/-72 tons) | C33: - | D33: 3 | E33: PULL | F33: 0 | G33: =D33*F33 -> 0 | H33: =G33*Inputs!$B$6 -> 0 | I33: 0 | J33: =D33*Inputs!$B$12 -> 1350 | K33: 0 | L33: =SUM(H33:K33) -> 1350
A34: S7 | B34: Tree / vegetative debris haul-off | C34: - | D34: 2 | E34: LOAD | F34: 0 | G34: =D34*F34 -> 0 | H34: =G34*Inputs!$B$6 -> 0 | I34: 0 | J34: =D34*Inputs!$B$11 -> 900 | K34: 0 | L34: =SUM(H34:K34) -> 900
B35: SITE BASE BID - man-hours / crew-days | G35: =SUM(G28:G34) -> 100.33 | H35: =ROUNDUP(G35/(Inputs!$B$7*Inputs!$B$8),0) -> 3
B36: Direct cost | L36: =SUM(L28:L34) -> 7608.25
B37: Contingency | L37: =L36*Inputs!$B$10 -> 380.4125
B38: Profit ($/crew-day x crew-days) | L38: =Inputs!$B$9*H35 -> 3000
B39: SITE BASE BID TOTAL | L39: =SUM(L36:L38) -> 10988.663
A41: ALTERNATE #1 - EXTERIOR CMU WALL REMOVAL (ANGLED ENTRIES)
A42: A1.1 | B42: Remove exterior CMU walls at angled entries (+/-67 LF x +/-12') | C42: A1 'Demo exterior CMU wall' | D42: 804 | E42: SF | F42: 0.15 | G42: =D42*F42 -> 120.6 | H42: =G42*Inputs!$B$6 -> 3015 | I42: 0 | J42: 0 | K42: 0 | L42: =SUM(H42:K42) -> 3015
A43: A1.2 | B43: Wall saw / chainsaw rental & blades | C43: - | D43: 2 | E43: DAY | F43: 0 | G43: =D43*F43 -> 0 | H43: =G43*Inputs!$B$6 -> 0 | I43: =D43*450 -> 900 | J43: 0 | K43: 0 | L43: =SUM(H43:K43) -> 900
...

Sheet Flooring - Wayne's
A1: WAYNE'S CARPET PLUS - FLOORING ESTIMATE
A2: Palms Medical Group / Lake Shore Hospital Authority - 351 NE Franklin St, Lake City FL | A5 Finish Plan & Finish Schedule
M3: FLOORING MARKUP - A5 FINISH PLAN (CT / LVT / shower tile by room)
A4: Item | B4: Description | C4: Net Qty | D4: Unit | E4: Waste | F4: Order Qty | G4: Material $/U | H4: Labor $/U | I4: Material $ | J4: Labor $ | K4: Total $
A5: F1 | B5: Carpet tile - Mohawk 559 Anodized Lapis (CT rooms + corridors) | C5: 4948 | D5: SF | E5: =Inputs!$B$17 -> 0.07 | F5: =ROUNDUP(C5*(1+E5),0) -> 5295 | G5: =Inputs!$B$14+Inputs!$B$15 -> 3.45 | H5: =Inputs!$B$16 -> 0.85 | I5: =F5*G5 -> 18267.75 | J5: =C5*H5 -> 4205.8 | K5: =I5+J5 -> 22473.55
A6: F2 | B6: LVT - Flexco Natural Elements American Cherry 610 (glue-down) | C6: 3147 | D6: SF | E6: =Inputs!$B$21 -> 0.08 | F6: =ROUNDUP(C6*(1+E6),0) -> 3399 | G6: =Inputs!$B$18+Inputs!$B$19 -> 3.75 | H6: =Inputs!$B$20 -> 1.4 | I6: =F6*G6 -> 12746.25 | J6: =C6*H6 -> 4405.8 | K6: =I6+J6 -> 17152.05
A7: F3 | B7: 2x2 sheet ceramic shower floor tile - ADA Tlt 124 | C7: 13 | D7: SF | F7: =ROUNDUP(C7*(1+E7),0) -> 13 | G7: =Inputs!$B$22 -> 14 | H7: =Inputs!$B$23 -> 18 | I7: =F7*G7 -> 182 | J7: =C7*H7 -> 234 | K7: =MAX(I7+J7,Inputs!$B$24) -> 650
A8: F4 | B8: Floor prep - patch / skim after demo (allowance) | C8: 8095 | D8: SF | F8: =ROUNDUP(C8*(1+E8),0) -> 8095 | H8: =Inputs!$B$25 -> 0.45 | I8: =F8*G8 -> 0 | J8: =C8*H8 -> 3642.75 | K8: =I8+J8 -> 3642.75
A9: F5 | B9: Transition strips between dissimilar floors (max 1/8") | C9: 30 | D9: EA | F9: =ROUNDUP(C9*(1+E9),0) -> 30 | H9: =Inputs!$B$26 -> 65 | I9: =F9*G9 -> 0 | J9: =C9*H9 -> 1950 | K9: =I9+J9 -> 1950
A10: F6 | B10: Freight / delivery | C10: 1 | D10: LS | F10: =ROUNDUP(C10*(1+E10),0) -> 1 | G10: =Inputs!$B$27 -> 450 | I10: =F10*G10 -> 450 | J10: =C10*H10 -> 0 | K10: =I10+J10 -> 450
B12: Subtotal (material + labor) | K12: =SUM(K5:K10) -> 46318.35
B13: Overhead & profit | K13: =K12*Inputs!$B$28 -> 11579.587
B14: FLOORING TOTAL - WAYNE'S CARPET PLUS | K14: =K12+K13 -> 57897.938
B16: Price per SF of flooring | K16: =K14/(C5+C6) -> 7.1523085
B18: Room takeoff (from A5 markup)
B19: Room / area | C19: SF | D19: Finish
B20: 122 Break/Conf | C20: 633 | D20: CT
B21: 123 ADA Tlt | C21: 62 | D21: LVT
B22: 124 ADA Tlt | C22: 90 | D22: LVT
B23: 125 Provider | C23: 102 | D23: CT
B24: 126 Sto | C24: 24 | D24: LVT
B25: 128/130/132 Exam | C25: 308 | D25: LVT
B26: 127 Provider | C26: 103 | D26: CT
B27: 129/131/133 Exam | C27: 325 | D27: LVT
B28: Corridor C01 | C28: 564 | D28: CT
B29: Corridor N entry | C29: 56 | D29: CT
B30: Corridor link | C30: 47 | D30: CT
B31: Corridor C02 | C31: 776 | D31: CT
... B54: 141/143/147 Exam | C54: 335 | D54: LVT

Sheet Markup - Flooring A5
A1: MARKUP: Flooring A5 (full-size PDF: PMG_Lake_Shore_Markups.pdf)

Sheet Markup - Demo A1
A1: MARKUP: Demo A1 (full-size PDF: PMG_Lake_Shore_Markups.pdf)

Sheet Markup - Demo A1.1
A1: MARKUP: Demo A1.1 (full-size PDF: PMG_Lake_Shore_Markups.pdf)

Sheet Markup - Site Demo
A1: MARKUP: Site Demo (full-size PDF: PMG_Lake_Shore_Markups.pdf)

Sheet Markup - Floor Removal
A1: MARKUP: Floor Removal (full-size PDF: PMG_Lake_Shore_Markups.pdf)

Sheet Markup - Ceiling Removal
A1: MARKUP: Ceiling Removal (full-size PDF: PMG_Lake_Shore_Markups.pdf)
