Workbook

Sheet Summary & Scope
B1: HARBOR FREIGHT TOOLS - MOUNT PLEASANT PA | DEMOLITION BID (DISASSEMBLE DYNAMICS, INC.)
B2: Harbor Freight Tools - 819 Crossroads Plaza, Mount Pleasant PA 15666 | GC: Marco Contractors (job key hft8841) | ADA Architects D1.0 dated 09/14/26 | 18,280 GSF former Save A Lot | Bids were due 10/27/26 10:00 AM ET to Jayne Baxter, jbaxter@marcocontractors.com
B4: PRICE SUMMARY
B5: BASE BID - Interior + exterior/site demolition | C5: ='Demo Bid - DDD'!L103 -> 51100.402
B6: Alt #1 - CMU openings & infill removal | C6: ='Demo Bid - DDD'!L53 -> 7185.75
B7: Alt #2 - Plumbing trench sawcut & slab removal | C7: ='Demo Bid - DDD'!L64 -> 3978.75
B8: Alt #3 - Sawcutting at site removal limits | C8: ='Demo Bid - DDD'!L73 -> 2451
B9: Alt #4 - Floor cut-outs & interior curb | C9: ='Demo Bid - DDD'!L83 -> 2424.75
B10: Alt #5 - Mastic removal / grinding | C10: ='Demo Bid - DDD'!L92 -> 20137.125
B12: SCOPE OF WORK
B13: DEMOLITION SCOPE OF WORK
B14: 1. Remove all existing floor finishes throughout the HFT space, +/-18,060 SF (Plan Note 215, Gen. Note 16)
B15: 2. Remove fixtures (fixed or free-standing) and all abandoned equipment throughout the HFT space (Plan Notes 202, 203)
B16: 3. Remove light fixtures completely throughout the HFT space (Plan Note 212)
B17: 4. Remove abandoned electrical equipment not to be re-used incl. junction boxes, conduit and wiring, and unused wires and hangers, back to the nearest junction box (Plan Note 205, A2.0)
B18: 5. Remove exposed metal studs completely, +/-74 LF (+/-58'-8" and +/-14'-10") (Plan Note 207)
B19: 6. Remove existing gyp. bd. wall and associated furring (Plan Note 209)
B20: 7. Remove (2) existing overhead doors and frames and (1) hollow metal door and frame (Plan Notes 218, 221, 240)
B21: 8. Remove existing storefront doors and storefront system at new bi-parting entry, +/-12'-0" W x 10'-0" H, and portion of storefront +/-5'-2" W; knee wall to remain (Plan Notes 211, 219)
B22: 9. Remove existing canopy and all associated attachments at north door (Plan Note 247)
B23: 10. Remove existing signage (Plan Note 223)
... B53: - PA dumpster and equipment rates are placeholders - confirm locally

Sheet Inputs
A1: Harbor Freight Tools - Mount Pleasant PA | Demolition Estimate Inputs
A2: Blue = editable input. Yellow = assumption to confirm. All costs flow to the Demo Bid tab.
A4: Input | B4: Value | C4: Note
A5: Labor rate ($/MH, flat) | B5: 25 | C5: Standing input
A6: Crew size (men) | B6: 6 | C6: Standing input
A7: Shift length (hrs) | B7: 8 | C7: Day work; 8-week GC schedule starting 11/16/26
A8: Profit ($ per crew-day) | B8: 1000 | C8: Standing input
A9: Contingency (% of direct) | B9: 0.05 | C9: Standing input
A10: C&D dumpster 30 yd ($/pull) | B10: 650 | C10: Mount Pleasant PA rate not on file - confirm with local hauler
A11: Concrete/asphalt dumpster 20 yd ($/pull) | B11: 550 | C11: PA rate not on file - confirm
A12: Lodging ($/night, crew house) | B12: 265 | C12: Standing Airbnb rate; travel job ~900 mi from Lake City
A13: Per diem ($/man/day) | B13: 40 | C13: Standing input
A14: Include lodging & per diem? (1 = yes, 0 = no) | B14: 1 | C14: Set to 0 if a local PA crew is used
A15: Lodging nights per crew-day (incl. weekends) | B15: 1.4 | C15: 7 nights per 5 work days

Sheet Demo Bid - DDD
A1: DISASSEMBLE DYNAMICS, INC. - DEMOLITION BID BREAKOUT
A2: Harbor Freight Tools - 819 Crossroads Plaza, Mount Pleasant PA 15666 | GC: Marco Contractors (job key hft8841) | ADA Architects D1.0 dated 09/14/26
A3: Quantities scaled from D1.0 (3/32" = 1'-0") and plan dimensions - see markup tabs. Verify in field. | N3: DEMOLITION MARKUPS - D1.0 FULL SHEET, ENLARGED WEST, ENLARGED EAST
A5: # | B5: Description | C5: Ref | D5: Qty | E5: Unit | F5: MH / Unit | G5: MH | H5: Labor $ | I5: Equip / Rental $ | J5: Disposal $ | K5: Other $ | L5: Direct $
A6: BASE BID - INTERIOR DEMOLITION
A7: D1 | B7: Remove all existing floor finishes throughout (DDD-owned scraper) | C7: Note 215; Gen. Note 16 | D7: 18060 | E7: SF | F7: 0.01 | G7: =D7*F7 -> 180.6 | H7: =G7*Inputs!$B$5 -> 4515 | I7: 0 | J7: 0 | K7: 0 | L7: =SUM(H7:K7) -> 4515
A8: D2 | B8: Remove fixtures (fixed or free-standing) and abandoned equipment throughout | C8: Notes 202, 203 | D8: 18060 | E8: SF | F8: 0.003 | G8: =D8*F8 -> 54.18 | H8: =G8*Inputs!$B$5 -> 1354.5 | I8: 0 | J8: 0 | K8: 0 | L8: =SUM(H8:K8) -> 1354.5
A9: D3 | B9: Remove light fixtures completely throughout HFT space (high-bay / strip at +/-16'-18') | C9: Note 212 | D9: 150 | E9: EA | F9: 0.5 | G9: =D9*F9 -> 75 | H9: =G9*Inputs!$B$5 -> 1875 | I9: 0 | J9: 0 | K9: 0 | L9: =SUM(H9:K9) -> 1875
A10: D4 | B10: Remove abandoned electrical (j-boxes, conduit, wire) and unused wires/hangers back to nearest J-box | C10: Note 205; A2.0 | D10: 18060 | E10: SF | F10: 0.004 | G10: =D10*F10 -> 72.24 | H10: =G10*Inputs!$B$5 -> 1806 | I10: 0 | J10: 0 | K10: 0 | L10: =SUM(H10:K10) -> 1806
A11: D5 | B11: Remove exposed metal studs completely (+/-58'-8" west wall, +/-14'-10" east), +/-16' high | C11: Note 207 | D11: 74 | E11: LF | F11: 0.25 | G11: =D11*F11 -> 18.5 | H11: =G11*Inputs!$B$5 -> 462.5 | I11: 0 | J11: 0 | K11: 0 | L11: =SUM(H11:K11) -> 462.5
A12: D6 | B12: Remove existing gyp. bd. wall and associated furring (+/-2' section, north wall) | C12: Note 209 | D12: 1 | E12: EA | F12: 3 | G12: =D12*F12 -> 3 | H12: =G12*Inputs!$B$5 -> 75 | I12: 0 | J12: 0 | K12: 0 | L12: =SUM(H12:K12) -> 75
A13: D7 | B13: Remove existing overhead doors & frames (west wall) | C13: Notes 218, 240 | D13: 2 | E13: EA | F13: 6 | G13: =D13*F13 -> 12 | H13: =G13*Inputs!$B$5 -> 300 | I13: 0 | J13: 0 | K13: 0 | L13: =SUM(H13:K13) -> 300
A14: D8 | B14: Remove existing hollow metal door & frame (north wall) | C14: Note 221 | D14: 1 | E14: EA | F14: 2 | G14: =D14*F14 -> 2 | H14: =G14*Inputs!$B$5 -> 50 | I14: 0 | J14: 0 | K14: 0 | L14: =SUM(H14:K14) -> 50
A15: D9 | B15: Remove storefront doors & system at new bi-parting entry (+/-12'-0") and storefront portion (+/-5'-2"), knee wall to remain | C15: Notes 211, 219 | D15: 17 | E15: LF | F15: 1 | G15: =D15*F15 -> 17 | H15: =G15*Inputs!$B$5 -> 425 | I15: 0 | J15: 0 | K15: 0 | L15: =SUM(H15:K15) -> 425
A16: D10 | B16: Remove existing canopy and attachments at north door | C16: Note 247 | D16: 1 | E16: EA | F16: 4 | G16: =D16*F16 -> 4 | H16: =G16*Inputs!$B$5 -> 100 | I16: 0 | J16: 0 | K16: 0 | L16: =SUM(H16:K16) -> 100
A17: D11 | B17: Remove existing exterior signage (coordinate with landlord) | C17: Note 223 | D17: 1 | E17: LS | F17: 8 | G17: =D17*F17 -> 8 | H17: =G17*Inputs!$B$5 -> 200 | I17: 0 | J17: 0 | K17: 0 | L17: =SUM(H17:K17) -> 200
A18: D12 | B18: Load-out, protection of items to remain (telco demarc, fire riser, gas meter, elec. equipment), broom clean | C18: Gen. Notes 2, 11 | D18: 1 | E18: LS | F18: 40 | G18: =D18*F18 -> 40 | H18: =G18*Inputs!$B$5 -> 1000 | I18: 0 | J18: 0 | K18: 0 | L18: =SUM(H18:K18) -> 1000
A19: D13 | B19: 26' scissor lift for lights / studs / signage | C19: - | D19: 8 | E19: DAY | F19: 0 | G19: =D19*F19 -> 0 | H19: =G19*Inputs!$B$5 -> 0 | I19: =D19*175+250 -> 1650 | J19: 0 | K19: 0 | L19: =SUM(H19:K19) -> 1650
A20: D14 | B20: Consumables - blades, debris carts, bags, poly, PPE | C20: - | D20: 1 | E20: LS | F20: 0 | G20: =D20*F20 -> 0 | H20: =G20*Inputs!$B$5 -> 0 | I20: 0 | J20: 0 | K20: 1200 | L20: =SUM(H20:K20) -> 1200
A21: D15 | B21: C&D disposal - 30 yd dumpsters | C21: Gen. Note 5 | D21: 6 | E21: PULL | F21: 0 | G21: =D21*F21 -> 0 | H21: =G21*Inputs!$B$5 -> 0 | I21: 0 | J21: =D21*Inputs!$B$10 -> 3900 | K21: 0 | L21: =SUM(H21:K21) -> 3900
B22: INTERIOR BASE BID - man-hours / crew-days | G22: =SUM(G7:G21) -> 486.52 | H22: =MAX(1,ROUNDUP(G22/(Inputs!$B$6*Inputs!$B$7),0)) -> 11
B23: Direct cost | L23: =SUM(L7:L21) -> 18913
B24: Lodging & per diem (crew-days x nights factor x lodging + crew x per diem x crew-days) | L24: =Inputs!$B$14*H22*(Inputs!$B$15*Inputs!$B$12+Inputs!$B$6*Inputs!$B$13) -> 6721
B25: Contingency | L25: =L23*Inputs!$B$9 -> 945.65
B26: Profit ($/crew-day x crew-days) | L26: =Inputs!$B$8*H22 -> 11000
B27: INTERIOR BASE BID TOTAL | L27: =SUM(L23:L26) -> 37579.65
A29: BASE BID - EXTERIOR / SITE DEMOLITION
A30: S1 | B30: Remove existing receiving platform, rail, canopy, ramp and all attachments (west) | C30: Note 208 | D30: 871 | E30: SF | F30: 0.06 | G30: =D30*F30 -> 52.26 | H30: =G30*Inputs!$B$5 -> 1306.5 | I30: 0 | J30: 0 | K30: 0 | L30: =SUM(H30:K30) -> 1306.5
A31: S2 | B31: Remove asphalt for new concrete pad and receiving enclosure (west, net of platform) | C31: Note 224 | D31: 911 | E31: SF | F31: 0.01 | G31: =D31*F31 -> 9.11 | H31: =G31*Inputs!$B$5 -> 227.75 | I31: 0 | J31: 0 | K31: 0 | L31: =SUM(H31:K31) -> 227.75
A32: S3 | B32: Remove existing sloped asphalt (east) | C32: Note 227 | D32: 176 | E32: SF | F32: 0.012 | G32: =D32*F32 -> 2.112 | H32: =G32*Inputs!$B$5 -> 52.8 | I32: 0 | J32: 0 | K32: 0 | L32: =SUM(H32:K32) -> 52.8
A33: S4 | B33: Remove concrete walk for new egress ramp, accessible ramp, frost slab and sidewalk (east) | C33: Notes 225, 226, 228, 234 | D33: 916 | E33: SF | F33: 0.03 | G33: =D33*F33 -> 27.48 | H33: =G33*Inputs!$B$5 -> 687 | I33: 0 | J33: 0 | K33: 0 | L33: =SUM(H33:K33) -> 687
A34: S5 | B34: Remove existing bollards completely | C34: Note 246 | D34: 4 | E34: EA | F34: 2 | G34: =D34*F34 -> 8 | H34: =G34*Inputs!$B$5 -> 200 | I34: 0 | J34: 0 | K34: 0 | L34: =SUM(H34:K34) -> 200
A35: S6 | B35: Skid steer w/ breaker (4 days) + mini-excavator (3 days) incl. delivery | C35: - | D35: 1 | E35: LS | F35: 0 | G35: =D35*F35 -> 0 | H35: =G35*Inputs!$B$5 -> 0 | I35: 3600 | J35: 0 | K35: 0 | L35: =SUM(H35:K35) -> 3600
A36: S7 | B36: Concrete / asphalt disposal - 20 yd dumpsters (+/-45 tons) | C36: - | D36: 4 | E36: PULL | F36: 0 | G36: =D36*F36 -> 0 | H36: =G36*Inputs!$B$5 -> 0 | I36: 0 | J36: =D36*Inputs!$B$11 -> 2200 | K36: 0 | L36: =SUM(H36:K36) -> 2200
B37: SITE BASE BID - man-hours / crew-days | G37: =SUM(G30:G36) -> 98.962 | H37: =MAX(1,ROUNDUP(G37/(Inputs!$B$6*Inputs!$B$7),0)) -> 3
B38: Direct cost | L38: =SUM(L30:L36) -> 8274.05
B39: Lodging & per diem (crew-days x nights factor x lodging + crew x per diem x crew-days) | L39: =Inputs!$B$14*H37*(Inputs!$B$15*Inputs!$B$12+Inputs!$B$6*Inputs!$B$13) -> 1833
B40: Contingency | L40: =L38*Inputs!$B$9 -> 413.7025
B41: Profit ($/crew-day x crew-days) | L41: =Inputs!$B$8*H37 -> 3000
B42: SITE BASE BID TOTAL | L42: =SUM(L38:L41) -> 13520.753
...

Sheet Markup - D1.0 Demo Plan
A1: MARKUP: D1.0 Demo Plan (full-size PDF: HFT_Mt_Pleasant_Demo_Markup.pdf)

Sheet Markup - West Enlarged
A1: MARKUP: West Enlarged (full-size PDF: HFT_Mt_Pleasant_Demo_Markup.pdf)

Sheet Markup - East Enlarged
A1: MARKUP: East Enlarged (full-size PDF: HFT_Mt_Pleasant_Demo_Markup.pdf)
