Workbook

Sheet Summary & Scope
B1: AECHELON TECHNOLOGY - ORLANDO FL | DEMOLITION BID (DISASSEMBLE DYNAMICS, INC.)
B2: Aechelon Technology - 12633 Challenger Parkway, Suite 250/260, Orlando FL 32826 | GC: S.A. Casey Construction (Kelly Lehman) | Romero Trumpp Farmer Architects A1.01 / A1.02, Permit Set 09/14/2026 | Proposal DDD-2026/1027R1
B4: PRICE SUMMARY
B5: BASE BID | C5: ='Demo Bid - DDD'!L26 -> 17630
B6: Alternate No. 1 - remaining fluorescent fixtures throughout suite (approx. 60 EA) | C6: ='Demo Bid - DDD'!L36 -> 2660
B7: Unit price - each fixture beyond 60 EA | C7: ='Demo Bid - DDD'!L38 -> 45
B9: SCOPE OF WORK (as written in the proposal)
B10: OUR SCOPE OF WORK (INCLUSIONS)
B11: Demo existing walls at office/corridor fronts to the extent required for new door/frame or glass system openings, 12 locations, +/-101 LF (Plan Note 1)
B12: Demo existing interior partitions shown dashed, +/-175 LF (A1.01 Demolition Plan)
B13: Remove existing restroom plumbing fixtures, toilet partitions and finishes for refurbishment, 2 areas, +/-668 SF (Plan Note 2)
B14: Carefully remove existing data server racks and set aside for owner relocation (Plan Note 3)
B15: Remove existing door, frame and wall to the extent required for new 8'-0" door (Plan Note 5)
B16: Remove existing casework and plumbing fixtures, including REF/DW casework run, 3 locations, +/-25 LF (Plan Note 6)
B17: Remove existing ceiling grid and tile in areas shown, +/-2,371 SF; carefully remove and store acoustic ceiling tiles on site for reuse (Ceiling Note 3, RCP Gen. Note 1)
B18: Remove existing light fixtures as tagged, 75 EA (61 lay-in / 14 linear pendant) (Ceiling Note 1)
B19: Carefully remove existing track light, +/-12'-5", and turn over for relocation (Ceiling Note 2)
B20: Disconnect and remove electrical devices, boxes, plates and wiring in demolished walls back to the nearest junction box (Demo Gen. Note 10)
... B30: Removal of fluorescent fixtures beyond the 75 tagged is priced as Alternate No. 1 (RCP Gen. Note 3).

Sheet Inputs
A1: Aechelon Technology - Orlando FL | Demolition Estimate Inputs
A2: Blue = editable input. Yellow = assumption to confirm. All costs flow to the Demo Bid tab.
A4: Input | B4: Value | C4: Note
A5: Labor rate ($/MH, flat) | B5: 25 | C5: Standing input
A6: Crew size (men) | B6: 6 | C6: Standing input
A7: Shift length (hrs) | B7: 8 | C7: Day work assumed (night work not included per proposal)
A8: Profit ($ per crew-day) | B8: 1000 | C8: Standing input
A9: Contingency (% of direct) | B9: 0.05 | C9: Standing input
A10: C&D dumpster 30 yd ($/pull) | B10: 350 | C10: Orlando independent building / office park rate
A11: Lodging ($/night, crew house) | B11: 265 | C11: Lake City to Orlando ~2.5 hrs each way
A12: Per diem ($/man/day) | B12: 40 | C12: Standing input
A13: Include lodging & per diem? (1 = yes, 0 = no) | B13: 1 | C13: Set to 0 if crew commutes daily
A14: Lodging nights per crew-day | B14: 1 | C14: Short job - weeknights only

Sheet Demo Bid - DDD
A1: DISASSEMBLE DYNAMICS, INC. - DEMOLITION BID BREAKOUT
A2: Aechelon Technology - 12633 Challenger Parkway, Suite 250/260, Orlando FL 32826 | GC: S.A. Casey Construction (Kelly Lehman) | Romero Trumpp Farmer Architects A1.01 / A1.02, Permit Set 09/14/2026
A3: Quantities scaled from A1.01 / A1.02 at 1/8" = 1'-0" - see markup tabs. Verify in field. | N3: DEMOLITION MARKUPS - A1.01 DEMO PLAN / A1.02 DEMO RCP
A5: # | B5: Description | C5: Ref | D5: Qty | E5: Unit | F5: MH / Unit | G5: MH | H5: Labor $ | I5: Equip / Rental $ | J5: Disposal $ | K5: Other $ | L5: Direct $
A6: BASE BID - INTERIOR SELECTIVE DEMOLITION (A1.01 / A1.02)
A7: D1 | B7: Demo walls at office/corridor fronts for new door/frame or glass system openings, 12 locations (+/-101 LF) | C7: Plan Note 1 | D7: 101 | E7: LF | F7: 0.25 | G7: =D7*F7 -> 25.25 | H7: =G7*Inputs!$B$5 -> 631.25 | I7: 0 | J7: 0 | K7: 0 | L7: =SUM(H7:K7) -> 631.25
A8: D2 | B8: Demo interior partitions shown dashed (+/-175 LF) | C8: A1.01 legend | D8: 175 | E8: LF | F8: 0.25 | G8: =D8*F8 -> 43.75 | H8: =G8*Inputs!$B$5 -> 1093.75 | I8: 0 | J8: 0 | K8: 0 | L8: =SUM(H8:K8) -> 1093.75
A9: D3 | B9: Remove restroom plumbing fixtures, toilet partitions & finishes (after cap by plumber), 2 areas | C9: Plan Note 2 | D9: 668 | E9: SF | F9: 0.06 | G9: =D9*F9 -> 40.08 | H9: =G9*Inputs!$B$5 -> 1002 | I9: 0 | J9: 0 | K9: 0 | L9: =SUM(H9:K9) -> 1002
A10: D4 | B10: Carefully remove data server racks and set aside for owner relocation | C10: Plan Note 3 | D10: 1 | E10: EA | F10: 4 | G10: =D10*F10 -> 4 | H10: =G10*Inputs!$B$5 -> 100 | I10: 0 | J10: 0 | K10: 0 | L10: =SUM(H10:K10) -> 100
A11: D5 | B11: Remove door, frame & wall for new 8' door | C11: Plan Note 5 | D11: 1 | E11: EA | F11: 4 | G11: =D11*F11 -> 4 | H11: =G11*Inputs!$B$5 -> 100 | I11: 0 | J11: 0 | K11: 0 | L11: =SUM(H11:K11) -> 100
A12: D6 | B12: Remove casework & plumbing fixtures incl. REF/DW run, 3 locations | C12: Plan Note 6 | D12: 25 | E12: LF | F12: 0.4 | G12: =D12*F12 -> 10 | H12: =G12*Inputs!$B$5 -> 250 | I12: 0 | J12: 0 | K12: 0 | L12: =SUM(H12:K12) -> 250
A13: D7 | B13: Remove ceiling grid & tile - carefully remove and store ACT on site for reuse, 9 areas | C13: Ceiling Note 3; RCP Gen. Note 1 | D13: 2371 | E13: SF | F13: 0.02 | G13: =D13*F13 -> 47.42 | H13: =G13*Inputs!$B$5 -> 1185.5 | I13: 0 | J13: 0 | K13: 0 | L13: =SUM(H13:K13) -> 1185.5
A14: D8 | B14: Remove marked light fixtures (61 lay-in / 14 linear pendant) | C14: Ceiling Note 1 | D14: 75 | E14: EA | F14: 0.5 | G14: =D14*F14 -> 37.5 | H14: =G14*Inputs!$B$5 -> 937.5 | I14: 0 | J14: 0 | K14: 0 | L14: =SUM(H14:K14) -> 937.5
A15: D9 | B15: Carefully remove track light (+/-12'-5") and turn over for relocation | C15: Ceiling Note 2 | D15: 1 | E15: EA | F15: 1.5 | G15: =D15*F15 -> 1.5 | H15: =G15*Inputs!$B$5 -> 37.5 | I15: 0 | J15: 0 | K15: 0 | L15: =SUM(H15:K15) -> 37.5
A16: D10 | B16: Disconnect & remove devices, boxes, plates & wiring in demolished walls back to nearest J-box | C16: Demo Gen. Note 10 | D16: 276 | E16: LF | F16: 0.05 | G16: =D16*F16 -> 13.8 | H16: =G16*Inputs!$B$5 -> 345 | I16: 0 | J16: 0 | K16: 0 | L16: =SUM(H16:K16) -> 345
A17: D11 | B17: Salvage coordination, load-out, protection of items to remain, broom clean | C17: Demo Gen. Notes 8, 12, 15 | D17: 1 | E17: LS | F17: 16 | G17: =D17*F17 -> 16 | H17: =G17*Inputs!$B$5 -> 400 | I17: 0 | J17: 0 | K17: 0 | L17: =SUM(H17:K17) -> 400
A18: D12 | B18: Ladders / baker scaffold / debris carts | C18: - | D18: 1 | E18: LS | F18: 0 | G18: =D18*F18 -> 0 | H18: =G18*Inputs!$B$5 -> 0 | I18: 300 | J18: 0 | K18: 0 | L18: =SUM(H18:K18) -> 300
A19: D13 | B19: Consumables - blades, bags, poly, PPE | C19: - | D19: 1 | E19: LS | F19: 0 | G19: =D19*F19 -> 0 | H19: =G19*Inputs!$B$5 -> 0 | I19: 0 | J19: 0 | K19: 400 | L19: =SUM(H19:K19) -> 400
A20: D14 | B20: C&D disposal - 30 yd dumpsters | C20: Demo Gen. Note 8 | D20: 4 | E20: PULL | F20: 0 | G20: =D20*F20 -> 0 | H20: =G20*Inputs!$B$5 -> 0 | I20: 0 | J20: =D20*Inputs!$B$10 -> 1400 | K20: 0 | L20: =SUM(H20:K20) -> 1400
B21: BASE BID - man-hours / crew-days | G21: =SUM(G7:G20) -> 243.3 | H21: =MAX(1,ROUNDUP(G21/(Inputs!$B$6*Inputs!$B$7),0)) -> 6
B22: Direct cost | L22: =SUM(L7:L20) -> 8182.5
B23: Lodging & per diem | L23: =Inputs!$B$13*H21*(Inputs!$B$14*Inputs!$B$11+Inputs!$B$6*Inputs!$B$12) -> 3030
B24: Contingency | L24: =L22*Inputs!$B$9 -> 409.125
B25: Profit ($/crew-day x crew-days) | L25: =Inputs!$B$8*H21 -> 6000
B26: BASE BID TOTAL | L26: =ROUNDUP(SUM(L22:L25),-1) -> 17630
A28: ALTERNATE #1 - REMAINING FLUORESCENT FIXTURES THROUGHOUT SUITE (RCP GEN. NOTE 3)
A29: A1.1 | B29: Remove all remaining existing fluorescent fixtures throughout suite (not tagged) - approx. count | C29: RCP Gen. Note 3 | D29: 60 | E29: EA | F29: 0.5 | G29: =D29*F29 -> 30 | H29: =G29*Inputs!$B$5 -> 750 | I29: 0 | J29: 0 | K29: 0 | L29: =SUM(H29:K29) -> 750
A30: A1.2 | B30: C&D disposal | C30: - | D30: 1 | E30: PULL | F30: 0 | G30: =D30*F30 -> 0 | H30: =G30*Inputs!$B$5 -> 0 | I30: 0 | J30: =D30*Inputs!$B$10 -> 350 | K30: 0 | L30: =SUM(H30:K30) -> 350
B31: ALT #1 - man-hours / crew-days | G31: =SUM(G29:G30) -> 30 | H31: =MAX(1,ROUNDUP(G31/(Inputs!$B$6*Inputs!$B$7),0)) -> 1
B32: Direct cost | L32: =SUM(L29:L30) -> 1100
B33: Lodging & per diem | L33: =Inputs!$B$13*H31*(Inputs!$B$14*Inputs!$B$11+Inputs!$B$6*Inputs!$B$12) -> 505
B34: Contingency | L34: =L32*Inputs!$B$9 -> 55
B35: Profit ($/crew-day x crew-days) | L35: =Inputs!$B$8*H31 -> 1000
B36: ALT #1 TOTAL | L36: =ROUNDUP(SUM(L32:L35),-1) -> 2660
B38: Unit price for fixtures beyond the approx. count ($/EA) | L38: 45
A40: DEMOLITION BID SUMMARY
B41: BASE BID | H41: =H21 -> 6 | L41: =L26 -> 17630
B42: ALT #1 | H42: =H31 -> 1 | L42: =L36 -> 2660
B43: Base bid + Alt #1 | L43: =SUM(L41:L42) -> 20290
A45: EXPENSE BREAKDOWN BY COST TYPE
...

Sheet Markup - A1.01 Demo Plan
A1: MARKUP: A1.01 Demo Plan (full-size PDF: Aechelon_Demo_Markup.pdf)

Sheet Markup - A1.02 Demo RCP
A1: MARKUP: A1.02 Demo RCP (full-size PDF: Aechelon_Demo_Markup.pdf)
